Workbook

Sheet Summary
A1: CNG feature coverage — SoftHSM2 KSP over PKCS#11
A2: A Microsoft CNG Key Storage Provider implemented on top of a PKCS#11 v2.40+ layer, backed by SoftHSM2 and verified against a second, independent PKCS#11 token.
A3: As of 2026-10-17 · source of truth: softhsm_ksp/docs/feature-matrix.csv
A5: Headline
A6: Measure | B6: Count | C6: Share | D6: What it means
A7: Capabilities assessed | B7: =COUNTA('CNG Feature Matrix'!A2:A104) -> 103 | D7: One row per capability observed across shipping CNG KSPs (Microsoft, AWS CloudHSM, Utimaco, Thales, Entrust, Securosys).
A8: Yes — fully supported | B8: =COUNTIF('CNG Feature Matrix'!E2:E104,"Yes") -> 73 | C8: =B8/$B$7 -> 0.70873786 | D8: Implemented and exercised by the test suites. No known gap against the surveyed market.
A9: Partial — works with a caveat | B9: =COUNTIF('CNG Feature Matrix'!E2:E104,"Partial") -> 10 | C9: =B9/$B$7 -> 0.097087379 | D9: Implemented and usable, but with a limit that is stated rather than hidden — a non-standard identifier, a deliberate refusal, or one direction of a two-way feature.
A10: No — not supported | B10: =COUNTIF('CNG Feature Matrix'!E2:E104,"No") -> 20 | C10: =B10/$B$7 -> 0.19417476 | D10: Not implemented. Every one carries a recorded reason; none is an oversight.
A12: Why the open items are open
A13: Every Partial and No row, classified by what actually stands in the way. This is the question the counts above cannot answer.
A14: Reason | B14: Count | C14: Share of open | D14: Reading
A15: Deliberate position | B15: =COUNTIF('CNG Feature Matrix'!H2:H104,A15) -> 11 | C15: =IFERROR(B15/(COUNTIF('CNG Feature Matrix'!E2:E104,"Partial")+COUNTIF('CNG Feature Matrix'!E2:E104,"No")),0) -> 0.36666667 | D15: The provider chose this and the reason is recorded — HSM posture (keys are non-extractable), or a scope decision such as DES and DSA.
A16: Blocked: no PKCS#11 mechanism | B16: =COUNTIF('CNG Feature Matrix'!H2:H104,A16) -> 7 | C16: =IFERROR(B16/(COUNTIF('CNG Feature Matrix'!E2:E104,"Partial")+COUNTIF('CNG Feature Matrix'!E2:E104,"No")),0) -> 0.23333333 | D16: PKCS#11 offers no mechanism, so a portable provider cannot reach it however much code is written — key attestation, use counters, change notification.
A17: Blocked: CNG has no identifier or slot | B17: =COUNTIF('CNG Feature Matrix'!H2:H104,A17) -> 5 | C17: =IFERROR(B17/(COUNTIF('CNG Feature Matrix'!E2:E104,"Partial")+COUNTIF('CNG Feature Matrix'!E2:E104,"No")),0) -> 0.16666667 | D17: CNG itself has no algorithm identifier (EdDSA, HMAC, counter mode) or no function-table slot (ML-KEM). Blocked on Microsoft, not on this project.
A18: Blocked: hardware / commercial | B18: =COUNTIF('CNG Feature Matrix'!H2:H104,A18) -> 4 | C18: =IFERROR(B18/(COUNTIF('CNG Feature Matrix'!E2:E104,"Partial")+COUNTIF('CNG Feature Matrix'!E2:E104,"No")),0) -> 0.13333333 | D18: Needs real hardware, a purchased code-signing certificate, or a formal validation programme. Not an engineering task.
A19: Blocked: needs ncrypt_provider.h / Windows | B19: =COUNTIF('CNG Feature Matrix'!H2:H104,A19) -> 3 | C19: =IFERROR(B19/(COUNTIF('CNG Feature Matrix'!E2:E104,"Partial")+COUNTIF('CNG Feature Matrix'!E2:E104,"No")),0) -> 0.1 | D19: Needs the CPDK header and a Windows machine. THE HIGHEST-VALUE ITEM HERE — see the caveat below.
A20: Total open | B20: =(COUNTIF('CNG Feature Matrix'!E2:E104,"Partial")+COUNTIF('CNG Feature Matrix'!E2:E104,"No")) -> 30 | C20: =IFERROR(B20/$B$7,0) -> 0.29126214 | D20: Sums the five reasons above; it must equal Partial + No.
A22: Read this before quoting any number above
A23: The DLL is not built in CI. | B23: MSVC compiles nine of the ten source files clean at /W3 /WX, but ksp_main.c needs ncrypt_provider.h, which does not exist on a hosted Windows runner. A green CI run does not mean the provider builds. Every other figure in this workbook is measured on Linux against a PKCS#11 token, not on Windows through ncrypt.dll.
A24: "Yes" means implemented and tested, not shipped and certified. | B24: Coverage here is functional. It says nothing about FIPS validation, hardware protection or Authenticode signing, all of which are separate rows and all of which are No.
A25: The backend is interchangeable, and that is load-bearing. | B25: The provider advertises the intersection of what it maps and what the token reports via C_GetMechanismList. Features marked Yes may go dark on a token that lacks the mechanism — by design, not by failure.
A26: A mock agreeing with itself proved several of these wrong. | B26: Running the same sources against a second, independent PKCS#11 token (Kryoptic) found defects in ECDSA, X25519, Ed448, HMAC and AES key wrap that thousands of mock assertions had passed. Rows carrying evidence grade A for cryptographic operations are the ones proven that way.

Sheet CNG Feature Matrix
A1: ID | B1: Category | C1: CNG feature | D1: What it covers | E1: Supported | F1: Matrix status | G1: Evidence | H1: Why still open | I1: Effort | J1: What other CNG KSPs do | K1: Detail, reasoning and remedy
A2: IFACE-01 | B2: Provider interface | C2: GetKeyStorageInterface export | D2: Sole exported symbol; returns the KSP function table | E2: Yes | F2: Covered | G2: A | J2: All providers
A3: IFACE-02 | B3: Provider interface | C3: OpenProvider / FreeProvider | D3: Provider handle lifecycle | E3: Yes | F3: Covered | G3: A | J3: All providers
A4: IFACE-03 | B4: Provider interface | C4: GetProviderProperty | D4: Name / Version / ImplType | E4: Yes | F4: Covered | G4: A | J4: All providers
A5: IFACE-04 | B5: Provider interface | C5: SetProviderProperty | D5: NCRYPT_PIN_PROPERTY is implemented: the PIN is handed to the session layer, and because sessions open lazily a PIN set before the first cryptographic call is the one used to log in. Token selection is now writable too, by KSP_TOKEN_LABEL_PROPERTY or KSP_SLOT_PROPERTY, in the window between NCryptOpenStorageProvider and the first operation: the slot is bound on first use rather than during initialisation, so the choice is still open. After binding it is refused with NTE_INVALID_HANDLE rather than accepted and ignored, because PKCS#11 cannot move a session between tokens and a caller told its selection succeeded would keep using the old one. A selection naming no present token is an error, never a fallback. Verified against TWO real tokens with different labels, PINs and keys; a test with one token cannot distinguish a working selection from an ignored one. | E5: Yes | F5: Covered | G5: A | J5: Vendor-specific
A6: IFACE-05 | B6: Provider interface | C6: NotifyChangeKey | D6: Key-change notification handle | E6: Partial | F6: Partial | G6: A | H6: Blocked: no PKCS#11 mechanism | I6: L | J6: Microsoft KSP | K6: Was a no-op returning ERROR_SUCCESS with the caller's HANDLE never written, so an application registering for notification was told it had succeeded and then waited on an uninitialised handle. It now validates the provider and the flags, clears *phEvent and refuses registration with NTE_NOT_SUPPORTED; unregistering succeeds because there is nothing to tear down. Real support needs a key-change channel a PKCS#11 token does not have - there is no C_WaitForSlotEvent equivalent for objects, and polling C_FindObjects on a timer would be a fabrication rather than a notification.
A7: IFACE-06 | B7: Provider interface | C7: GetOperationProperty | D7: Async / overlapped operation state | E7: No | F7: Not covered | G7: B | H7: Blocked: no PKCS#11 mechanism | I7: L | J7: Microsoft KSP | K7: Returns NTE_NOT_SUPPORTED. Only needed for overlapped I/O; PKCS#11 is synchronous so there is nothing to report.
A8: IFACE-07 | B8: Provider interface | C8: PromptUser | D8: Interactive PIN / consent dialog | E8: No | F8: Not covered | G8: B | H8: Deliberate position | I8: L | J8: Smart card KSPs | K8: Returns NTE_NOT_SUPPORTED. Would need a UI thread and a window handle from NCRYPT_WINDOW_HANDLE_PROPERTY.
A9: IFACE-08 | B9: Provider interface | C9: FreeBuffer / FreeObject | D9: Provider-allocated memory release | E9: Yes | F9: Covered | G9: A | J9: All providers
A10: IFACE-09 | B10: Provider interface | C10: VerifySignature | D10: NCryptVerifySignature through the provider | E10: Yes | F10: Covered | G10: A | J10: All providers implement the slot
A11: TABLE-01 | B11: Provider interface | C11: Function table layout matches the SDK | D11: NCRYPT_KEY_STORAGE_FUNCTION_TABLE slot order and membership | E11: Partial | F11: Partial | G11: A | H11: Blocked: needs ncrypt_provider.h / Windows | I11: S | J11: All providers | K11: The table uses designated initialisers, so the SDK header assigns slots by name and a wrong NAME is a build error. Since session 14 eight provider-scoped slots are also signature-checked: their KSP prototype equals the documented public NCrypt one, so test_function_table.c assigns each to a pointer type copied from <ncrypt.h> and the build promotes incompatible-pointer-types to an error. That caught KSP_NotifyChangeKey taking an NCRYPT_KEY_HANDLE where the parameter is HANDLE *phEvent. Key-scoped slots cannot be checked this way - NCryptSignHash takes (hKey, ...) while the slot takes (hProvider, hKey, ...) - so full confirmation still needs ncrypt_provider.h.
A12: BUILD-01 | B12: Provider interface | C12: Builds for Windows at all | D12: The shipped artefact is a Windows DLL | E12: Partial | F12: Partial | G12: A | H12: Blocked: needs ncrypt_provider.h / Windows | I12: M | J12: All providers | K12: Phase 0 fixed all six root causes. MSVC compiles nine of the ten source files clean at /W3 /WX and links test_p11_layer. ksp_main.c cannot be built in hosted CI: ncrypt_provider.h does not exist on a windows-latest runner, established by a dir /s /b across C: and D: that returned only this repo's own test mock, after a WDK install that reported success. Needs a machine that has the header.
A13: BUILD-02 | B13: Provider interface | C13: Continuous integration | D13: Automated build and test on the target platform | E13: Yes | F13: Covered | G13: A | J13: All providers
A14: RSA-01 | B14: Asymmetric RSA | C14: RSA key generation | D14: 2048 / 3072 / 4096 bits | E14: Yes | F14: Covered | G14: A | J14: All providers
A15: RSA-02 | B15: Asymmetric RSA | C15: RSA 1024 and below | D15: 512-1024 bits | E15: Partial | F15: Partial | G15: B | H15: Deliberate position | I15: S | J15: MS Software KSP; Utimaco | K15: Build-time opt-in only. KSP_RSA_MIN_BITS defaults to 2048; a legacy build can lower it, but the shipped default still rejects <2048 with NTE_BAD_LEN. Deliberate: silently allowing 1024 would weaken every deployment.
A16: RSA-03 | B16: Asymmetric RSA | C16: RSA above 4096 | D16: 8192 / 16384 bits | E16: Yes | F16: Covered | G16: B | J16: MS Software KSP; Utimaco
A17: RSA-04 | B17: Asymmetric RSA | C17: RSA arbitrary size increments | D17: 64-bit (MS) or 8-bit (Utimaco) steps | E17: Yes | F17: Covered | G17: B | J17: MS Software KSP; Utimaco
A18: RSA-05 | B18: Asymmetric RSA | C18: Custom public exponent | D18: Exponent other than 65537 | E18: Yes | F18: Covered | G18: C | J18: Vendor-specific
A19: RSA-06 | B19: Asymmetric RSA | C19: PKCS#1 v1.5 signing | D19: SHA-1 / 256 / 384 / 512 | E19: Yes | F19: Covered | G19: A | J19: All providers
A20: RSA-07 | B20: Asymmetric RSA | C20: PSS signing | D20: SHA-1 / 256 / 384 / 512 with caller salt length | E20: Yes | F20: Covered | G20: B | J20: All providers
A21: RSA-08 | B21: Asymmetric RSA | C21: PSS with SHA-224 | D21: SHA-224 salt and MGF1 | E21: Yes | F21: Covered | G21: C | J21: Unknown
A22: RSA-09 | B22: Asymmetric RSA | C22: PKCS#1 v1.5 decryption | D22: AT_KEYEXCHANGE keys | E22: Yes | F22: Covered | G22: A | J22: All providers
A23: RSA-10 | B23: Asymmetric RSA | C23: OAEP decryption | D23: SHA-1 / 224 / 256 / 384 / 512 | E23: Yes | F23: Covered | G23: A | J23: All providers
A24: RSA-11 | B24: Asymmetric RSA | C24: OAEP application label | D24: pbLabel / cbLabel passed through | E24: Yes | F24: Covered | G24: C | J24: Unknown
A25: RSA-12 | B25: Asymmetric RSA | C25: Raw RSA (no padding) | D25: CKM_RSA_X_509 | E25: Yes | F25: Covered | G25: A | J25: Some HSMs
A26: ECDSA-01 | B26: Asymmetric ECDSA | C26: ECDSA P-256 | D26: secp256r1; 64-byte signature | E26: Yes | F26: Covered | G26: A | J26: All providers
A27: ECDSA-02 | B27: Asymmetric ECDSA | C27: ECDSA P-384 | D27: secp384r1; 96-byte signature | E27: Yes | F27: Covered | G27: A | J27: All providers
... A36: ECDH-05 | B36: Key agreement | C36: BCRYPT_KDF_HMAC / TLS_PRF / HKDF | D36: Protocol-specific KDFs | E36: Yes | F36: Covered | G36: B | J36: MS Software KSP
A37: ECDH-06 | B37: Key agreement | C37: Finite-field Diffie-Hellman | D37: DH 512-4096 | E37: No | F37: Not covered | G37: B | H37: Deliberate position | I37: L | J37: MS Software KSP | K37: Out of scope by choice. ECDH supersedes it and no surveyed HSM KSP exposes it. Would need CKM_DH_PKCS_KEY_PAIR_GEN plus CKM_DH_PKCS_DERIVE.
A38: EDDSA-01 | B38: Asymmetric EdDSA | C38: Ed25519 signing | D38: 64-byte raw signature | E38: Partial | F38: Partial | G38: A | H38: Blocked: CNG has no identifier or slot | I38: N/A | J38: None | K38: Works against SoftHSM2 AND verified end to end against Kryoptic (session 10), but uses the non-standard identifier EDDSA_ED25519. CNG defines no EdDSA algorithm ID so no stock application can request it. Nothing to fix in the KSP; blocked on Microsoft.
A39: EDDSA-02 | B39: Asymmetric EdDSA | C39: Ed448 signing | D39: 114-byte raw signature | E39: Partial | F39: Partial | G39: A | H39: Blocked: CNG has no identifier or slot | I39: N/A | J39: None | K39: Same constraint as EDDSA-01. Note that Ed448 signing did not in fact work until session 10: CKM_EDDSA requires CK_EDDSA_PARAMS for Ed448 and the provider sent none. SoftHSM2 tolerates its absence, so this was invisible until a second token refused it.
A40: EDDSA-03 | B40: Asymmetric EdDSA | C40: X25519 key agreement | D40: Curve25519 ECDH | E40: Yes | F40: Covered | G40: A | J40: MS CNG has BCRYPT_ECC_CURVE_25519
A41: DSA-01 | B41: Asymmetric DSA | C41: DSA signing | D41: 512-1024 bits | E41: No | F41: Not covered | G41: B | H41: Deliberate position | I41: L | J41: MS Software KSP | K41: Deliberately out of scope. Deprecated in modern Windows PKI and absent from every HSM KSP surveyed.
A42: PQC-01 | B42: Post-quantum | C42: ML-DSA (Dilithium) | D42: FIPS 204 | E42: Partial | F42: Partial | G42: A | H42: Blocked: needs ncrypt_provider.h / Windows | I42: M | J42: Microsoft Software KSP (GA late 2025; AD CS ML-DSA enrolment May 2026). Thales Luna firmware 7.9+ and Entrust nShield XC/5/nSaaS ship it in the device; whether their CNG providers expose it is not established | K42: ML-DSA is wired through the KSP and gated on the capability probe: mechanism resolution, CKA_PARAMETER_SET key generation for all three parameter sets, key reopen, and signing. Verified end to end in session 10 against Kryoptic built with its pqc feature over OpenSSL 3.5.8 — generation, reopen by parameter set, and signature at the exact size for ML-DSA-44/65/87. Unreachable on SoftHSM2 2.7.0, which defines the mechanisms and implements none of them. Still Partial for one reason only: public key export is refused, because the CNG post-quantum key blob layout is in a Windows SDK header not available here. That is the same blocker as BUILD-01 and no backend fixes it.
A43: PQC-02 | B43: Post-quantum | C43: ML-KEM (Kyber) | D43: FIPS 203 | E43: No | F43: Not covered | G43: B | H43: Blocked: CNG has no identifier or slot | I43: L | J43: Microsoft CNG GA (BCrypt side). Thales and Entrust device firmware. No KSP-side exposure established for any provider | K43: NOT the same blocker as PQC-01. The probe recognises CKM_ML_KEM, so the backend is not what stops this: encapsulation and decapsulation have no slot in the NCRYPT_KEY_STORAGE_FUNCTION_TABLE this provider implements, so a KSP can hold an ML-KEM key with no entry point to use it. Whether a newer ncrypt_provider.h adds such slots cannot be determined here — same missing header as BUILD-01.
A44: PQC-03 | B44: Post-quantum | C44: LMS / XMSS | D44: Stateful hash-based signatures | E44: No | F44: Not covered | G44: C | H44: Blocked: no PKCS#11 mechanism | I44: L | J44: Thales Luna, Entrust nShield (device claims only) | K44: Blocked at the backend, unlike PQC-01: no PKCS#11 v3.2 token surveyed implements LMS or XMSS. Stateful schemes also need one-time-key state persistence the KSP has no model for, and a lost state update forges signatures.
A45: AES-01 | B45: Symmetric AES | C45: AES key generation | D45: 128 / 192 / 256 bits | E45: Yes | F45: Covered | G45: A | J45: None via KSP
A46: AES-02 | B46: Symmetric AES | C46: AES-ECB | D46: No IV | E46: Yes | F46: Covered | G46: A | J46: None via KSP
A47: AES-03 | B47: Symmetric AES | C47: AES-CBC | D47: 16-byte IV | E47: Yes | F47: Covered | G47: A | J47: None via KSP
A48: AES-04 | B48: Symmetric AES | C48: AES-CBC with padding | D48: NCRYPT_PAD_CIPHER_FLAG | E48: Yes | F48: Covered | G48: A | J48: None via KSP
...

Sheet By Category
A1: Coverage by capability area
A3: Category | B3: Yes | C3: Partial | D3: No | E3: Total | F3: % fully covered
A4: Asymmetric DSA | B4: =COUNTIFS('CNG Feature Matrix'!B2:B104,$A4,'CNG Feature Matrix'!E2:E104,"Yes") -> 0 | C4: =COUNTIFS('CNG Feature Matrix'!B2:B104,$A4,'CNG Feature Matrix'!E2:E104,"Partial") -> 0 | D4: =COUNTIFS('CNG Feature Matrix'!B2:B104,$A4,'CNG Feature Matrix'!E2:E104,"No") -> 1 | E4: =SUM(B4:D4) -> 1 | F4: =IFERROR(B4/E4,0) -> 0
A5: Asymmetric ECDSA | B5: =COUNTIFS('CNG Feature Matrix'!B2:B104,$A5,'CNG Feature Matrix'!E2:E104,"Yes") -> 6 | C5: =COUNTIFS('CNG Feature Matrix'!B2:B104,$A5,'CNG Feature Matrix'!E2:E104,"Partial") -> 0 | D5: =COUNTIFS('CNG Feature Matrix'!B2:B104,$A5,'CNG Feature Matrix'!E2:E104,"No") -> 0 | E5: =SUM(B5:D5) -> 6 | F5: =IFERROR(B5/E5,0) -> 1
A6: Asymmetric EdDSA | B6: =COUNTIFS('CNG Feature Matrix'!B2:B104,$A6,'CNG Feature Matrix'!E2:E104,"Yes") -> 1 | C6: =COUNTIFS('CNG Feature Matrix'!B2:B104,$A6,'CNG Feature Matrix'!E2:E104,"Partial") -> 2 | D6: =COUNTIFS('CNG Feature Matrix'!B2:B104,$A6,'CNG Feature Matrix'!E2:E104,"No") -> 0 | E6: =SUM(B6:D6) -> 3 | F6: =IFERROR(B6/E6,0) -> 0.33333333
A7: Asymmetric RSA | B7: =COUNTIFS('CNG Feature Matrix'!B2:B104,$A7,'CNG Feature Matrix'!E2:E104,"Yes") -> 11 | C7: =COUNTIFS('CNG Feature Matrix'!B2:B104,$A7,'CNG Feature Matrix'!E2:E104,"Partial") -> 1 | D7: =COUNTIFS('CNG Feature Matrix'!B2:B104,$A7,'CNG Feature Matrix'!E2:E104,"No") -> 0 | E7: =SUM(B7:D7) -> 12 | F7: =IFERROR(B7/E7,0) -> 0.91666667
A8: Key agreement | B8: =COUNTIFS('CNG Feature Matrix'!B2:B104,$A8,'CNG Feature Matrix'!E2:E104,"Yes") -> 5 | C8: =COUNTIFS('CNG Feature Matrix'!B2:B104,$A8,'CNG Feature Matrix'!E2:E104,"Partial") -> 0 | D8: =COUNTIFS('CNG Feature Matrix'!B2:B104,$A8,'CNG Feature Matrix'!E2:E104,"No") -> 1 | E8: =SUM(B8:D8) -> 6 | F8: =IFERROR(B8/E8,0) -> 0.83333333
A9: Key formats | B9: =COUNTIFS('CNG Feature Matrix'!B2:B104,$A9,'CNG Feature Matrix'!E2:E104,"Yes") -> 6 | C9: =COUNTIFS('CNG Feature Matrix'!B2:B104,$A9,'CNG Feature Matrix'!E2:E104,"Partial") -> 0 | D9: =COUNTIFS('CNG Feature Matrix'!B2:B104,$A9,'CNG Feature Matrix'!E2:E104,"No") -> 4 | E9: =SUM(B9:D9) -> 10 | F9: =IFERROR(B9/E9,0) -> 0.6
A10: Key lifecycle | B10: =COUNTIFS('CNG Feature Matrix'!B2:B104,$A10,'CNG Feature Matrix'!E2:E104,"Yes") -> 8 | C10: =COUNTIFS('CNG Feature Matrix'!B2:B104,$A10,'CNG Feature Matrix'!E2:E104,"Partial") -> 0 | D10: =COUNTIFS('CNG Feature Matrix'!B2:B104,$A10,'CNG Feature Matrix'!E2:E104,"No") -> 0 | E10: =SUM(B10:D10) -> 8 | F10: =IFERROR(B10/E10,0) -> 1
A11: Key properties | B11: =COUNTIFS('CNG Feature Matrix'!B2:B104,$A11,'CNG Feature Matrix'!E2:E104,"Yes") -> 13 | C11: =COUNTIFS('CNG Feature Matrix'!B2:B104,$A11,'CNG Feature Matrix'!E2:E104,"Partial") -> 0 | D11: =COUNTIFS('CNG Feature Matrix'!B2:B104,$A11,'CNG Feature Matrix'!E2:E104,"No") -> 4 | E11: =SUM(B11:D11) -> 17 | F11: =IFERROR(B11/E11,0) -> 0.76470588
A12: Operational | B12: =COUNTIFS('CNG Feature Matrix'!B2:B104,$A12,'CNG Feature Matrix'!E2:E104,"Yes") -> 7 | C12: =COUNTIFS('CNG Feature Matrix'!B2:B104,$A12,'CNG Feature Matrix'!E2:E104,"Partial") -> 0 | D12: =COUNTIFS('CNG Feature Matrix'!B2:B104,$A12,'CNG Feature Matrix'!E2:E104,"No") -> 5 | E12: =SUM(B12:D12) -> 12 | F12: =IFERROR(B12/E12,0) -> 0.58333333
A13: Post-quantum | B13: =COUNTIFS('CNG Feature Matrix'!B2:B104,$A13,'CNG Feature Matrix'!E2:E104,"Yes") -> 0 | C13: =COUNTIFS('CNG Feature Matrix'!B2:B104,$A13,'CNG Feature Matrix'!E2:E104,"Partial") -> 1 | D13: =COUNTIFS('CNG Feature Matrix'!B2:B104,$A13,'CNG Feature Matrix'!E2:E104,"No") -> 2 | E13: =SUM(B13:D13) -> 3 | F13: =IFERROR(B13/E13,0) -> 0
A14: Provider interface | B14: =COUNTIFS('CNG Feature Matrix'!B2:B104,$A14,'CNG Feature Matrix'!E2:E104,"Yes") -> 7 | C14: =COUNTIFS('CNG Feature Matrix'!B2:B104,$A14,'CNG Feature Matrix'!E2:E104,"Partial") -> 3 | D14: =COUNTIFS('CNG Feature Matrix'!B2:B104,$A14,'CNG Feature Matrix'!E2:E104,"No") -> 2 | E14: =SUM(B14:D14) -> 12 | F14: =IFERROR(B14/E14,0) -> 0.58333333
A15: Symmetric AES | B15: =COUNTIFS('CNG Feature Matrix'!B2:B104,$A15,'CNG Feature Matrix'!E2:E104,"Yes") -> 8 | C15: =COUNTIFS('CNG Feature Matrix'!B2:B104,$A15,'CNG Feature Matrix'!E2:E104,"Partial") -> 2 | D15: =COUNTIFS('CNG Feature Matrix'!B2:B104,$A15,'CNG Feature Matrix'!E2:E104,"No") -> 0 | E15: =SUM(B15:D15) -> 10 | F15: =IFERROR(B15/E15,0) -> 0.8
A16: Symmetric MAC | B16: =COUNTIFS('CNG Feature Matrix'!B2:B104,$A16,'CNG Feature Matrix'!E2:E104,"Yes") -> 1 | C16: =COUNTIFS('CNG Feature Matrix'!B2:B104,$A16,'CNG Feature Matrix'!E2:E104,"Partial") -> 1 | D16: =COUNTIFS('CNG Feature Matrix'!B2:B104,$A16,'CNG Feature Matrix'!E2:E104,"No") -> 0 | E16: =SUM(B16:D16) -> 2 | F16: =IFERROR(B16/E16,0) -> 0.5
A17: Symmetric legacy | B17: =COUNTIFS('CNG Feature Matrix'!B2:B104,$A17,'CNG Feature Matrix'!E2:E104,"Yes") -> 0 | C17: =COUNTIFS('CNG Feature Matrix'!B2:B104,$A17,'CNG Feature Matrix'!E2:E104,"Partial") -> 0 | D17: =COUNTIFS('CNG Feature Matrix'!B2:B104,$A17,'CNG Feature Matrix'!E2:E104,"No") -> 1 | E17: =SUM(B17:D17) -> 1 | F17: =IFERROR(B17/E17,0) -> 0
A18: All categories | B18: =SUM(B4:B17) -> 73 | C18: =SUM(C4:C17) -> 10 | D18: =SUM(D4:D17) -> 20 | E18: =SUM(E4:E17) -> 103 | F18: =IFERROR(B18/E18,0) -> 0.70873786

Sheet Open Items
A1: ID | B1: Category | C1: CNG feature | D1: Supported | E1: Why still open | F1: Outside this repo? | G1: Effort | H1: What works today | I1: What the blocker rests on | J1: What would actually close it
A2: BUILD-01 | B2: Provider interface | C2: Builds for Windows at all | D2: Partial | E2: Blocked: needs ncrypt_provider.h / Windows | F2: Outside | G2: M | H2: MSVC compiles nine of the ten source files clean at /W3 /WX and links test_p11_layer.exe. The mingw cross-compile is clean on all ten minus ksp_main.c. | I2: ncrypt_provider.h, which declares NCRYPT_KEY_STORAGE_FUNCTION_TABLE. A dir /s /b across C: and D: on a windows-latest runner returned only this repository's own test mock, after a WDK install that reported success. It is not in the Windows SDK. | J2: Phase 0 fixed all six root causes. MSVC compiles nine of the ten source files clean at /W3 /WX and links test_p11_layer. ksp_main.c cannot be built in hosted CI: ncrypt_provider.h does not exist on a windows-latest runner, established by a dir /s /b across C: and D: that returned only this repo's own test mock, after a WDK install that reported success. Needs a machine that has the header.
A3: PQC-01 | B3: Post-quantum | C3: ML-DSA (Dilithium) | D3: Partial | E3: Blocked: needs ncrypt_provider.h / Windows | F3: Outside | G3: M | H3: ML-DSA generates, reopens by parameter set and signs at all three sets, verified against Kryoptic built with its pqc feature over OpenSSL 3.5.8. Gated on the capability probe, so it is dark on SoftHSM2 and live on a v3.2 token. | I3: The CNG post-quantum key blob layout, which is in a Windows SDK header not available here. Public key export is the only thing missing. A guessed layout would pass every test here and fail only on Windows — the BCRYPT_SHA224_ALGORITHM mistake exactly. | J3: ML-DSA is wired through the KSP and gated on the capability probe: mechanism resolution, CKA_PARAMETER_SET key generation for all three parameter sets, key reopen, and signing. Verified end to end in session 10 against Kryoptic built with its pqc feature over OpenSSL 3.5.8 — generation, reopen by parameter set, and signature at the exact size for ML-DSA-44/65/87. Unreachable on SoftHSM2 2.7.0, which defines the mechanisms and implements none of them. Still Partial for one reason only: public key export is refused, because the CNG post-quantum key blob layout is in a Windows SDK header not available here. That is the same blocker as BUILD-01 and no backend fixes it.
A4: TABLE-01 | B4: Provider interface | C4: Function table layout matches the SDK | D4: Partial | E4: Blocked: needs ncrypt_provider.h / Windows | F4: Outside | G4: S | H4: Designated initialisers make a wrong slot NAME a build error. Eight provider-scoped slots are also signature-checked against <ncrypt.h>, which is what caught KSP_NotifyChangeKey holding an NCRYPT_KEY_HANDLE where the parameter is HANDLE *phEvent. | I4: The same missing header. Key-scoped slots cannot be checked against the public prototype, because it is not the slot's shape: NCryptSignHash takes (hKey, ...) while the slot takes (hProvider, hKey, ...). Asserting the public shape there would be inventing a fact. | J4: The table uses designated initialisers, so the SDK header assigns slots by name and a wrong NAME is a build error. Since session 14 eight provider-scoped slots are also signature-checked: their KSP prototype equals the documented public NCrypt one, so test_function_table.c assigns each to a pointer type copied from <ncrypt.h> and the build promotes incompatible-pointer-types to an error. That caught KSP_NotifyChangeKey taking an NCRYPT_KEY_HANDLE where the parameter is HANDLE *phEvent. Key-scoped slots cannot be checked this way - NCryptSignHash takes (hKey, ...) while the slot takes (hProvider, hKey, ...) - so full confirmation still needs ncrypt_provider.h.
A5: AES-06 | B5: Symmetric AES | C5: AES-CTR | D5: Partial | E5: Blocked: CNG has no identifier or slot | F5: Outside | G5: N/A | H5: AES-CTR encrypts and decrypts, verified against a live token, selected through NCRYPT_CHAINING_MODE_PROPERTY. | I5: CNG defines no counter-mode chaining string, so ChainingModeCTR is a provider extension that no stock application will select. | J5: Works but ChainingModeCTR is a KSP extension. CNG defines no standard counter-mode string so no stock application will select it.
A6: EDDSA-01 | B6: Asymmetric EdDSA | C6: Ed25519 signing | D6: Partial | E6: Blocked: CNG has no identifier or slot | F6: Outside | G6: N/A | H6: Ed25519 signs, and is verified end to end against Kryoptic. The absent CK_EDDSA_PARAMS that selects the pure context-free form is deliberate and fault-injected. | I6: CNG defines no EdDSA algorithm identifier at all, so EDDSA_ED25519 is this provider's own string and no stock application will ask for it. Nothing in the KSP can change that. | J6: Works against SoftHSM2 AND verified end to end against Kryoptic (session 10), but uses the non-standard identifier EDDSA_ED25519. CNG defines no EdDSA algorithm ID so no stock application can request it. Nothing to fix in the KSP; blocked on Microsoft.
A7: EDDSA-02 | B7: Asymmetric EdDSA | C7: Ed448 signing | D7: Partial | E7: Blocked: CNG has no identifier or slot | F7: Outside | G7: N/A | H7: Ed448 signs against Kryoptic with CK_EDDSA_PARAMS supplied, which Ed448 requires and Ed25519 must not have. The asymmetry is deliberate and both mistakes are fault-injected. It did NOT work before session 10: SoftHSM2 tolerates the missing parameter, so a second token was needed to see it. | I7: Same as EDDSA-01 — no CNG identifier exists. | J7: Same constraint as EDDSA-01. Note that Ed448 signing did not in fact work until session 10: CKM_EDDSA requires CK_EDDSA_PARAMS for Ed448 and the provider sent none. SoftHSM2 tolerates its absence, so this was invisible until a second token refused it.
A8: HMAC-01 | B8: Symmetric MAC | C8: HMAC-SHA1 / 256 / 384 / 512 | D8: Partial | E8: Blocked: CNG has no identifier or slot | F8: Outside | G8: N/A | H8: HMAC signing works over CKM_SHA*_HMAC for SHA-1 through SHA-512, verified against a live token. It had never actually worked before session 10 — KSP_SignHash passed hPrivKey unconditionally and secret keys live in hSecretKey. | I8: CNG reaches HMAC through BCrypt algorithm handles, not through KSP key algorithms, so HMAC_SHA* are this provider's own identifiers. | J8: Works against SoftHSM2 but HMAC_SHA* are our own identifiers. CNG does HMAC through BCrypt algorithm handles not KSP key algorithms.
A9: PQC-02 | B9: Post-quantum | C9: ML-KEM (Kyber) | D9: No | E9: Blocked: CNG has no identifier or slot | F9: Outside | G9: L | H9: The probe recognises CKM_ML_KEM, so the backend is not the obstacle. Nothing is advertised, deliberately. | I9: The function table has no slot for encapsulation or decapsulation, so a KSP could hold an ML-KEM key with no entry point to use it. Whether a newer ncrypt_provider.h adds such slots cannot be established here — the same missing header. | J9: NOT the same blocker as PQC-01. The probe recognises CKM_ML_KEM, so the backend is not what stops this: encapsulation and decapsulation have no slot in the NCRYPT_KEY_STORAGE_FUNCTION_TABLE this provider implements, so a KSP can hold an ML-KEM key with no entry point to use it. Whether a newer ncrypt_provider.h adds such slots cannot be determined here — same missing header as BUILD-01.
A10: FMT-10 | B10: Key formats | C10: OPAQUETRANSPORT blob | D10: No | E10: Blocked: no PKCS#11 mechanism | F10: Outside | G10: L | H10: Nothing. Not advertised. | I10: OPAQUETRANSPORT has no defined wrapping format to follow, so there is no standard to implement against — only a format this provider would invent and no one else could read. | J10: Would let keys move between instances of the same provider. Needs a defined wrapping format; no standard to follow.
A11: IFACE-05 | B11: Provider interface | C11: NotifyChangeKey | D11: Partial | E11: Blocked: no PKCS#11 mechanism | F11: Outside | G11: L | H11: Validates the provider and flags, clears *phEvent and refuses registration with NTE_NOT_SUPPORTED. Unregistering succeeds, because there is nothing to tear down. Before session 14 it returned ERROR_SUCCESS without writing the handle, so a caller waited on an uninitialised HANDLE. | I11: PKCS#11 has no object-change channel: there is no C_WaitForSlotEvent equivalent for objects. Polling C_FindObjects on a timer would be a fabrication dressed as a notification. THIS IS THE ROW CLOSEST IN SHAPE TO the three that were wrongly called deliberate — it would become actionable the moment a backend offered such a channel, so it is worth re-reading rather than inheriting. | J11: Was a no-op returning ERROR_SUCCESS with the caller's HANDLE never written, so an application registering for notification was told it had succeeded and then waited on an uninitialised handle. It now validates the provider and the flags, clears *phEvent and refuses registration with NTE_NOT_SUPPORTED; unregistering succeeds because there is nothing to tear down. Real support needs a key-change channel a PKCS#11 token does not have - there is no C_WaitForSlotEvent equivalent for objects, and polling C_FindObjects on a timer would be a fabrication rather than a notification.
A12: IFACE-06 | B12: Provider interface | C12: GetOperationProperty | D12: No | E12: Blocked: no PKCS#11 mechanism | F12: Outside | G12: L | H12: Refused with NTE_NOT_SUPPORTED. | I12: The property reports on an asynchronous operation and PKCS#11 is synchronous, so there is no operation state to report however much code is written. This row sat in the deliberate column until the pairing check was run against its own text, which already said "a fact about PKCS#11 rather than about this code" — so it was mislabelled by the person who wrote the reason, and the cross-check is what caught it. | J12: Returns NTE_NOT_SUPPORTED. Only needed for overlapped I/O; PKCS#11 is synchronous so there is nothing to report.
... A31: RSA-02 | B31: Asymmetric RSA | C31: RSA 1024 and below | D31: Partial | E31: Deliberate position | F31: Our choice | G31: S | H31: Any multiple of 64 from KSP_RSA_MIN_BITS to 16384. A legacy build can lower the floor; the shipped default refuses below 2048 with NTE_BAD_LEN. | I31: A security choice, not a constraint: the mechanism exists and the code path works. Silently allowing 1024 would weaken every deployment that did not ask for it, so it is an opt-in at build time rather than a refusal. | J31: Build-time opt-in only. KSP_RSA_MIN_BITS defaults to 2048; a legacy build can lower it, but the shipped default still rejects <2048 with NTE_BAD_LEN. Deliberate: silently allowing 1024 would weaken every deployment.
A33: Gaps outside this matrix’s scope
A34: The matrix tracks capabilities observed across shipping CNG KSPs — the market. A defect in this provider’s OWN conformance surface is not one of those, so no row here would ever point at it. That blind spot has now cost three findings, so they are listed explicitly.
A36: Gap | B36: Detail | C36: How it was found | D36: Status
A37: Key-scoped function table slots are unverifiable | B37: The mock types every slot as void *, so a wrong parameter TYPE is not a build error on Linux, and MSVC cannot compile ksp_main.c without ncrypt_provider.h. Eight provider-scoped slots are now checked against <ncrypt.h>; key-scoped ones cannot be, because the public prototype is not the slot's shape. | C37: Session 14, by asking why KSP_NotifyChangeKey had survived with the wrong parameter type. | D37: Tracked as TABLE-01, which is the one matrix row that does cover a conformance question rather than a capability.

Sheet Legend
A1: How to read this workbook
A3: Supported
A4: Yes | B4: Implemented and exercised by the test suites. No known gap against the capabilities observed in shipping CNG KSPs.
A5: Partial | B5: Implemented and usable with a stated limit: a provider-specific identifier no stock application will ask for, a deliberate refusal, or one working direction of a two-way feature.
A6: No | B6: Not implemented. Each carries a recorded reason — see "Why still open".
A8: Evidence grade
A9: A | B9: Established inside this repository — read from the source, a header, or proven by a test. The strongest grade and the only one used for this provider's own behaviour.
A10: B | B10: Vendor documentation or a documentation mirror. Used for what other products do.
A11: C | B11: Inference from indirect sources. Used sparingly and never for a claim about this provider.
A13: Effort
A14: S / M / L | B14: Rough size of the remedy IF it were unblocked. It is not a schedule, and a small effort behind a hard blocker is still not startable — TABLE-01 is S and needs a Windows machine.
A15: (blank) | B15: No remedy is planned: the row is a deliberate position or an external blocker.
A17: Test layers behind "Yes"
A18: Layer 1 | B18: 22 unit suites, 1816 assertions, Linux/GCC against a controllable PKCS#11 mock. Pins down the provider's logic; cannot validate assumptions about real tokens.
A19: Layer 1b | B19: The same provider sources against Kryoptic, an independent PKCS#11 token in Rust. 256 assertions, run twice against one token so anything left behind is caught. Plus 33 concurrency assertions across 32 threads under ThreadSanitizer, and - behind TWO tokens on one module - 53 for token selection and 28 for per-scope isolation, because a single token cannot tell a working selection from an ignored one.
A20: Layer 2 / 3 | B20: Windows integration and HLK-conformant PowerShell suites. Written and syntax-checked; they need a Windows machine with SoftHSM2 to execute.
A22: Scope
A23: What this measures | B23: The CNG key-storage surface, as observed across Microsoft Software/Platform Crypto, AWS CloudHSM, Utimaco, Thales, Entrust and Securosys, assessed against this provider.
A24: What it does not | B24: Performance, deployment, packaging, and anything about the SoftHSM2 token itself beyond what the provider depends on.
A26: Provenance
A27: Content fingerprint: 6ae4217b85c8 | B27: A digest of feature-matrix.csv, coverage_blockers.py, gap_detail.py and this workbook’s generator. tests/check_generated_artifacts.py recomputes it: if the matrix was edited and the workbook was not regenerated, the two disagree and CI fails. Byte-comparing the file itself cannot work — an xlsx is a zip, and neither member order nor timestamps are stable.
